Workbook
Name Slicer_Representative: #N/A

Sheet pivot
A3: Call Count | B3: Total Amount | C3: Call Duration | D3: Avg Rating | E3: 5 * Cusromers
A4: 1000 | B4: 96623 | C4: 89850 | D4: 3.8854 | E4: 307
A10: Call Count | B10: Total Amount | C10: Call Duration | D10: Avg Rating | E10: 5 * Cusromers
A11: 218 | B11: 20581 | C11: 19300 | D11: 3.8706422 | E11: 74
A14: Row Labels | B14: Call Count | C14: Call Count2 | E14: Row Labels | F14: Call Count
A15: Jan | B15: 19 | C15: 19 | E15: Sunday | F15: 28
A16: Feb | B16: 10 | C16: 10 | E16: Monday | F16: 24
A17: Mar | B17: 40 | C17: 40 | E17: Tuesday | F17: 44
A18: Apr | B18: 40 | C18: 40 | E18: Wednesday | F18: 36
A19: May | B19: 13 | C19: 13 | E19: Thursday | F19: 33
A20: Jun | B20: 12 | C20: 12 | E20: Friday | F20: 29
A21: Jul | B21: 9 | C21: 9 | E21: Saturday | F21: 24
A22: Aug | B22: 13 | C22: 13 | E22: Grand Total | F22: 218
A23: Sep | B23: 18 | C23: 18
A24: Oct | B24: 21 | C24: 21
A25: Nov | B25: 14 | C25: 14
A26: Dec | B26: 9 | C26: 9
A27: Grand Total | B27: 218 | C27: 218 | E27: selected rep | F27: =B51 -> R02
E29: For graph
E30: Rep | F30: Call | G30: Amount | H30: Sel Call | I30: Sel Amount
A31: Row Labels | B31: Call Count | C31: Total Amount | E31: =A32 -> R01 | F31: =B32 -> 189 | G31: =C32 -> 18415 | H31: =IF(E31=$F$27,F31,NA()) -> #N/A | I31: =IF(E31=$F$27,G31,NA()) -> #N/A
A32: R01 | B32: 189 | C32: 18415 | E32: =A33 -> R02 | F32: =B33 -> 218 | G32: =C33 -> 20581 | H32: =IF(E32=$F$27,F32,NA()) -> 218 | I32: =IF(E32=$F$27,G32,NA()) -> 20581
A33: R02 | B33: 218 | C33: 20581 | E33: =A34 -> R03 | F33: =B34 -> 207 | G33: =C34 -> 20872 | H33: =IF(E33=$F$27,F33,NA()) -> #N/A | I33: =IF(E33=$F$27,G33,NA()) -> #N/A
A34: R03 | B34: 207 | C34: 20872 | E34: =A35 -> R04 | F34: =B35 -> 186 | G34: =C35 -> 16651 | H34: =IF(E34=$F$27,F34,NA()) -> #N/A | I34: =IF(E34=$F$27,G34,NA()) -> #N/A
A35: R04 | B35: 186 | C35: 16651 | E35: =A36 -> R05 | F35: =B36 -> 200 | G35: =C36 -> 20104 | H35: =IF(E35=$F$27,F35,NA()) -> #N/A | I35: =IF(E35=$F$27,G35,NA()) -> #N/A
A36: R05 | B36: 200 | C36: 20104
A37: Grand Total | B37: 1000 | C37: 96623
A40: Call Count | B40: Column Labels | F40: Row Labels | G40: Call Count
A41: Row Labels | B41: Female | C41: Male | D41: Grand Total | F41: 1 | G41: 3
A42: Cincinnati | B42: 144 | C42: 133 | D42: 277 | F42: 2 | G42: 19
A43: Cleveland | B43: 325 | C43: 63 | D43: 388 | F43: 3 | G43: 35
A44: Columbus | B44: 129 | C44: 206 | D44: 335 | F44: 4 | G44: 87
A45: Grand Total | B45: 598 | C45: 402 | D45: 1000 | F45: 5 | G45: 74
F46: Grand Total | G46: 218
B50: Row Labels | E50: Total Amount | F50: Column Labels
B51: R02 | E51: Row Labels | F51: R01 | G51: R02 | H51: R03 | I51: R04 | J51: R05 | K51: Grand Total
E52: Cincinnati
E53: C0003 | F53: 891 | G53: 1332 | H53: 1282 | I53: 739 | J53: 560 | K53: 4804
E54: C0004 | F54: 1991 | G54: 1982 | H54: 1206 | I54: 884 | J54: 1722 | K54: 7785
E55: C0011 | F55: 1163 | G55: 1180 | H55: 1616 | I55: 1043 | J55: 1747 | K55: 6749
...

Sheet Data
B1: Call Centre Data
B3: Call number | C3: Customer ID | D3: Duration | E3: Representative | F3: Date of Call | G3: Purchase Amount | H3: Satisfaction Rating | I3: FY | J3: Day of week | K3: Duration Bucket | L3: Rating rounded | Q3: Customer ID | R3: Gedner | S3: Age | T3: City
B4: Call_7271 | C4: C0003 | D4: 116 | E4: R05 | F4: 44927 | G4: 128 | H4: 4.9 | I4: =IF(MONTH(calls[[#This Row],[Date of Call]])<=6, YEAR(calls[[#This Row],[Date of Call]]), YEAR(calls[[#This Row],[Date of Call]])+1) -> 2023 | J4: =TEXT(calls[[#This Row],[Date of Call]],"DDDD") -> Sunday | K4: {=_xlfn.IFS(calls[[#This Row],[Duration]]<=10,"Under 10 mins", calls[[#This Row],[Duration]]<=30, "10 to 30 mins", calls[[#This Row],[Duration]]<=60, "30 to 60 mins", calls[[#This Row],[Duration]]<=120, "1 to 2 hours", TRUE, "More than 2 hours")} -> 1 to 2 hours | L4: =ROUND(calls[[#This Row],[Satisfaction Rating]],0) -> 5 | Q4: C0001 | R4: Male | S4: 41 | T4: Columbus
B5: Call_7272 | C5: C0004 | D5: 119 | E5: R05 | F5: 44927 | G5: 135 | H5: 2.9 | I5: =IF(MONTH(calls[[#This Row],[Date of Call]])<=6, YEAR(calls[[#This Row],[Date of Call]]), YEAR(calls[[#This Row],[Date of Call]])+1) -> 2023 | J5: =TEXT(calls[[#This Row],[Date of Call]],"DDDD") -> Sunday | K5: {=_xlfn.IFS(calls[[#This Row],[Duration]]<=10,"Under 10 mins", calls[[#This Row],[Duration]]<=30, "10 to 30 mins", calls[[#This Row],[Duration]]<=60, "30 to 60 mins", calls[[#This Row],[Duration]]<=120, "1 to 2 hours", TRUE, "More than 2 hours")} -> 1 to 2 hours | L5: =ROUND(calls[[#This Row],[Satisfaction Rating]],0) -> 3 | Q5: C0002 | R5: Male | S5: 31 | T5: Cleveland
B6: Call_7273 | C6: C0005 | D6: 68 | E6: R02 | F6: 44927 | G6: 66 | H6: 4.7 | I6: =IF(MONTH(calls[[#This Row],[Date of Call]])<=6, YEAR(calls[[#This Row],[Date of Call]]), YEAR(calls[[#This Row],[Date of Call]])+1) -> 2023 | J6: =TEXT(calls[[#This Row],[Date of Call]],"DDDD") -> Sunday | K6: {=_xlfn.IFS(calls[[#This Row],[Duration]]<=10,"Under 10 mins", calls[[#This Row],[Duration]]<=30, "10 to 30 mins", calls[[#This Row],[Duration]]<=60, "30 to 60 mins", calls[[#This Row],[Duration]]<=120, "1 to 2 hours", TRUE, "More than 2 hours")} -> 1 to 2 hours | L6: =ROUND(calls[[#This Row],[Satisfaction Rating]],0) -> 5 | Q6: C0003 | R6: Male | S6: 26 | T6: Cincinnati
B7: Call_7274 | C7: C0014 | D7: 119 | E7: R02 | F7: 44927 | G7: 22 | H7: 2.9 | I7: =IF(MONTH(calls[[#This Row],[Date of Call]])<=6, YEAR(calls[[#This Row],[Date of Call]]), YEAR(calls[[#This Row],[Date of Call]])+1) -> 2023 | J7: =TEXT(calls[[#This Row],[Date of Call]],"DDDD") -> Sunday | K7: {=_xlfn.IFS(calls[[#This Row],[Duration]]<=10,"Under 10 mins", calls[[#This Row],[Duration]]<=30, "10 to 30 mins", calls[[#This Row],[Duration]]<=60, "30 to 60 mins", calls[[#This Row],[Duration]]<=120, "1 to 2 hours", TRUE, "More than 2 hours")} -> 1 to 2 hours | L7: =ROUND(calls[[#This Row],[Satisfaction Rating]],0) -> 3 | Q7: C0004 | R7: Male | S7: 36 | T7: Cincinnati
B8: Call_7275 | C8: C0011 | D8: 128 | E8: R01 | F8: 44928 | G8: 31 | H8: 2.8 | I8: =IF(MONTH(calls[[#This Row],[Date of Call]])<=6, YEAR(calls[[#This Row],[Date of Call]]), YEAR(calls[[#This Row],[Date of Call]])+1) -> 2023 | J8: =TEXT(calls[[#This Row],[Date of Call]],"DDDD") -> Monday | K8: {=_xlfn.IFS(calls[[#This Row],[Duration]]<=10,"Under 10 mins", calls[[#This Row],[Duration]]<=30, "10 to 30 mins", calls[[#This Row],[Duration]]<=60, "30 to 60 mins", calls[[#This Row],[Duration]]<=120, "1 to 2 hours", TRUE, "More than 2 hours")} -> More than 2 hours | L8: =ROUND(calls[[#This Row],[Satisfaction Rating]],0) -> 3 | Q8: C0005 | R8: Male | S8: 37 | T8: Columbus
B9: Call_7276 | C9: C0011 | D9: 49 | E9: R02 | F9: 44929 | G9: 135 | H9: 4.8 | I9: =IF(MONTH(calls[[#This Row],[Date of Call]])<=6, YEAR(calls[[#This Row],[Date of Call]]), YEAR(calls[[#This Row],[Date of Call]])+1) -> 2023 | J9: =TEXT(calls[[#This Row],[Date of Call]],"DDDD") -> Tuesday | K9: {=_xlfn.IFS(calls[[#This Row],[Duration]]<=10,"Under 10 mins", calls[[#This Row],[Duration]]<=30, "10 to 30 mins", calls[[#This Row],[Duration]]<=60, "30 to 60 mins", calls[[#This Row],[Duration]]<=120, "1 to 2 hours", TRUE, "More than 2 hours")} -> 30 to 60 mins | L9: =ROUND(calls[[#This Row],[Satisfaction Rating]],0) -> 5 | Q9: C0006 | R9: Male | S9: 23 | T9: Columbus
B10: Call_7277 | C10: C0007 | D10: 84 | E10: R05 | F10: 44929 | G10: 60 | H10: 4.7 | I10: =IF(MONTH(calls[[#This Row],[Date of Call]])<=6, YEAR(calls[[#This Row],[Date of Call]]), YEAR(calls[[#This Row],[Date of Call]])+1) -> 2023 | J10: =TEXT(calls[[#This Row],[Date of Call]],"DDDD") -> Tuesday | K10: {=_xlfn.IFS(calls[[#This Row],[Duration]]<=10,"Under 10 mins", calls[[#This Row],[Duration]]<=30, "10 to 30 mins", calls[[#This Row],[Duration]]<=60, "30 to 60 mins", calls[[#This Row],[Duration]]<=120, "1 to 2 hours", TRUE, "More than 2 hours")} -> 1 to 2 hours | L10: =ROUND(calls[[#This Row],[Satisfaction Rating]],0) -> 5 | Q10: C0007 | R10: Female | S10: 22 | T10: Cleveland
B11: Call_7278 | C11: C0003 | D11: 103 | E11: R04 | F11: 44929 | G11: 148 | H11: 4.4 | I11: =IF(MONTH(calls[[#This Row],[Date of Call]])<=6, YEAR(calls[[#This Row],[Date of Call]]), YEAR(calls[[#This Row],[Date of Call]])+1) -> 2023 | J11: =TEXT(calls[[#This Row],[Date of Call]],"DDDD") -> Tuesday | K11: {=_xlfn.IFS(calls[[#This Row],[Duration]]<=10,"Under 10 mins", calls[[#This Row],[Duration]]<=30, "10 to 30 mins", calls[[#This Row],[Duration]]<=60, "30 to 60 mins", calls[[#This Row],[Duration]]<=120, "1 to 2 hours", TRUE, "More than 2 hours")} -> 1 to 2 hours | L11: =ROUND(calls[[#This Row],[Satisfaction Rating]],0) -> 4 | Q11: C0008 | R11: Female | S11: 42 | T11: Cleveland
B12: Call_7279 | C12: C0005 | D12: 31 | E12: R02 | F12: 44929 | G12: 135 | H12: 3.6 | I12: =IF(MONTH(calls[[#This Row],[Date of Call]])<=6, YEAR(calls[[#This Row],[Date of Call]]), YEAR(calls[[#This Row],[Date of Call]])+1) -> 2023 | J12: =TEXT(calls[[#This Row],[Date of Call]],"DDDD") -> Tuesday | K12: {=_xlfn.IFS(calls[[#This Row],[Duration]]<=10,"Under 10 mins", calls[[#This Row],[Duration]]<=30, "10 to 30 mins", calls[[#This Row],[Duration]]<=60, "30 to 60 mins", calls[[#This Row],[Duration]]<=120, "1 to 2 hours", TRUE, "More than 2 hours")} -> 30 to 60 mins | L12: =ROUND(calls[[#This Row],[Satisfaction Rating]],0) -> 4 | Q12: C0009 | R12: Female | S12: 25 | T12: Columbus
B13: Call_7280 | C13: C0010 | D13: 44 | E13: R03 | F13: 44929 | G13: 105 | H13: 2.9 | I13: =IF(MONTH(calls[[#This Row],[Date of Call]])<=6, YEAR(calls[[#This Row],[Date of Call]]), YEAR(calls[[#This Row],[Date of Call]])+1) -> 2023 | J13: =TEXT(calls[[#This Row],[Date of Call]],"DDDD") -> Tuesday | K13: {=_xlfn.IFS(calls[[#This Row],[Duration]]<=10,"Under 10 mins", calls[[#This Row],[Duration]]<=30, "10 to 30 mins", calls[[#This Row],[Duration]]<=60, "30 to 60 mins", calls[[#This Row],[Duration]]<=120, "1 to 2 hours", TRUE, "More than 2 hours")} -> 30 to 60 mins | L13: =ROUND(calls[[#This Row],[Satisfaction Rating]],0) -> 3 | Q13: C0010 | R13: Female | S13: 30 | T13: Cleveland
B14: Call_7281 | C14: C0011 | D14: 102 | E14: R02 | F14: 44929 | G14: 69 | H14: 4.9 | I14: =IF(MONTH(calls[[#This Row],[Date of Call]])<=6, YEAR(calls[[#This Row],[Date of Call]]), YEAR(calls[[#This Row],[Date of Call]])+1) -> 2023 | J14: =TEXT(calls[[#This Row],[Date of Call]],"DDDD") -> Tuesday | K14: {=_xlfn.IFS(calls[[#This Row],[Duration]]<=10,"Under 10 mins", calls[[#This Row],[Duration]]<=30, "10 to 30 mins", calls[[#This Row],[Duration]]<=60, "30 to 60 mins", calls[[#This Row],[Duration]]<=120, "1 to 2 hours", TRUE, "More than 2 hours")} -> 1 to 2 hours | L14: =ROUND(calls[[#This Row],[Satisfaction Rating]],0) -> 5 | Q14: C0011 | R14: Female | S14: 30 | T14: Cincinnati
B15: Call_7282 | C15: C0013 | D15: 135 | E15: R05 | F15: 44929 | G15: 46 | H15: 3.4 | I15: =IF(MONTH(calls[[#This Row],[Date of Call]])<=6, YEAR(calls[[#This Row],[Date of Call]]), YEAR(calls[[#This Row],[Date of Call]])+1) -> 2023 | J15: =TEXT(calls[[#This Row],[Date of Call]],"DDDD") -> Tuesday | K15: {=_xlfn.IFS(calls[[#This Row],[Duration]]<=10,"Under 10 mins", calls[[#This Row],[Duration]]<=30, "10 to 30 mins", calls[[#This Row],[Duration]]<=60, "30 to 60 mins", calls[[#This Row],[Duration]]<=120, "1 to 2 hours", TRUE, "More than 2 hours")} -> More than 2 hours | L15: =ROUND(calls[[#This Row],[Satisfaction Rating]],0) -> 3 | Q15: C0012 | R15: Female | S15: 28 | T15: Cincinnati
... B18: Call_7285 | C18: C0013 | D18: 48 | E18: R01 | F18: 44930 | G18: 68 | H18: 4.9 | I18: =IF(MONTH(calls[[#This Row],[Date of Call]])<=6, YEAR(calls[[#This Row],[Date of Call]]), YEAR(calls[[#This Row],[Date of Call]])+1) -> 2023 | J18: =TEXT(calls[[#This Row],[Date of Call]],"DDDD") -> Wednesday | K18: {=_xlfn.IFS(calls[[#This Row],[Duration]]<=10,"Under 10 mins", calls[[#This Row],[Duration]]<=30, "10 to 30 mins", calls[[#This Row],[Duration]]<=60, "30 to 60 mins", calls[[#This Row],[Duration]]<=120, "1 to 2 hours", TRUE, "More than 2 hours")} -> 30 to 60 mins | L18: =ROUND(calls[[#This Row],[Satisfaction Rating]],0) -> 5 | Q18: C0015 | R18: Female | S18: 43 | T18: Cleveland
B19: Call_7286 | C19: C0010 | D19: 176 | E19: R05 | F19: 44931 | G19: 24 | H19: 4.8 | I19: =IF(MONTH(calls[[#This Row],[Date of Call]])<=6, YEAR(calls[[#This Row],[Date of Call]]), YEAR(calls[[#This Row],[Date of Call]])+1) -> 2023 | J19: =TEXT(calls[[#This Row],[Date of Call]],"DDDD") -> Thursday | K19: {=_xlfn.IFS(calls[[#This Row],[Duration]]<=10,"Under 10 mins", calls[[#This Row],[Duration]]<=30, "10 to 30 mins", calls[[#This Row],[Duration]]<=60, "30 to 60 mins", calls[[#This Row],[Duration]]<=120, "1 to 2 hours", TRUE, "More than 2 hours")} -> More than 2 hours | L19: =ROUND(calls[[#This Row],[Satisfaction Rating]],0) -> 5
B20: Call_7287 | C20: C0010 | D20: 99 | E20: R01 | F20: 44931 | G20: 195 | H20: 3.9 | I20: =IF(MONTH(calls[[#This Row],[Date of Call]])<=6, YEAR(calls[[#This Row],[Date of Call]]), YEAR(calls[[#This Row],[Date of Call]])+1) -> 2023 | J20: =TEXT(calls[[#This Row],[Date of Call]],"DDDD") -> Thursday | K20: {=_xlfn.IFS(calls[[#This Row],[Duration]]<=10,"Under 10 mins", calls[[#This Row],[Duration]]<=30, "10 to 30 mins", calls[[#This Row],[Duration]]<=60, "30 to 60 mins", calls[[#This Row],[Duration]]<=120, "1 to 2 hours", TRUE, "More than 2 hours")} -> 1 to 2 hours | L20: =ROUND(calls[[#This Row],[Satisfaction Rating]],0) -> 4
B21: Call_7288 | C21: C0009 | D21: 28 | E21: R03 | F21: 44931 | G21: 28 | H21: 3.8 | I21: =IF(MONTH(calls[[#This Row],[Date of Call]])<=6, YEAR(calls[[#This Row],[Date of Call]]), YEAR(calls[[#This Row],[Date of Call]])+1) -> 2023 | J21: =TEXT(calls[[#This Row],[Date of Call]],"DDDD") -> Thursday | K21: {=_xlfn.IFS(calls[[#This Row],[Duration]]<=10,"Under 10 mins", calls[[#This Row],[Duration]]<=30, "10 to 30 mins", calls[[#This Row],[Duration]]<=60, "30 to 60 mins", calls[[#This Row],[Duration]]<=120, "1 to 2 hours", TRUE, "More than 2 hours")} -> 10 to 30 mins | L21: =ROUND(calls[[#This Row],[Satisfaction Rating]],0) -> 4
B22: Call_7289 | C22: C0007 | D22: 54 | E22: R02 | F22: 44931 | G22: 170 | H22: 4.3 | I22: =IF(MONTH(calls[[#This Row],[Date of Call]])<=6, YEAR(calls[[#This Row],[Date of Call]]), YEAR(calls[[#This Row],[Date of Call]])+1) -> 2023 | J22: =TEXT(calls[[#This Row],[Date of Call]],"DDDD") -> Thursday | K22: {=_xlfn.IFS(calls[[#This Row],[Duration]]<=10,"Under 10 mins", calls[[#This Row],[Duration]]<=30, "10 to 30 mins", calls[[#This Row],[Duration]]<=60, "30 to 60 mins", calls[[#This Row],[Duration]]<=120, "1 to 2 hours", TRUE, "More than 2 hours")} -> 30 to 60 mins | L22: =ROUND(calls[[#This Row],[Satisfaction Rating]],0) -> 4
B23: Call_7290 | C23: C0006 | D23: 48 | E23: R05 | F23: 44932 | G23: 30 | H23: 4.4 | I23: =IF(MONTH(calls[[#This Row],[Date of Call]])<=6, YEAR(calls[[#This Row],[Date of Call]]), YEAR(calls[[#This Row],[Date of Call]])+1) -> 2023 | J23: =TEXT(calls[[#This Row],[Date of Call]],"DDDD") -> Friday | K23: {=_xlfn.IFS(calls[[#This Row],[Duration]]<=10,"Under 10 mins", calls[[#This Row],[Duration]]<=30, "10 to 30 mins", calls[[#This Row],[Duration]]<=60, "30 to 60 mins", calls[[#This Row],[Duration]]<=120, "1 to 2 hours", TRUE, "More than 2 hours")} -> 30 to 60 mins | L23: =ROUND(calls[[#This Row],[Satisfaction Rating]],0) -> 4
B24: Call_7291 | C24: C0004 | D24: 128 | E24: R05 | F24: 44932 | G24: 72 | H24: 5 | I24: =IF(MONTH(calls[[#This Row],[Date of Call]])<=6, YEAR(calls[[#This Row],[Date of Call]]), YEAR(calls[[#This Row],[Date of Call]])+1) -> 2023 | J24: =TEXT(calls[[#This Row],[Date of Call]],"DDDD") -> Friday | K24: {=_xlfn.IFS(calls[[#This Row],[Duration]]<=10,"Under 10 mins", calls[[#This Row],[Duration]]<=30, "10 to 30 mins", calls[[#This Row],[Duration]]<=60, "30 to 60 mins", calls[[#This Row],[Duration]]<=120, "1 to 2 hours", TRUE, "More than 2 hours")} -> More than 2 hours | L24: =ROUND(calls[[#This Row],[Satisfaction Rating]],0) -> 5
B25: Call_7292 | C25: C0004 | D25: 38 | E25: R04 | F25: 44933 | G25: 92 | H25: 4.9 | I25: =IF(MONTH(calls[[#This Row],[Date of Call]])<=6, YEAR(calls[[#This Row],[Date of Call]]), YEAR(calls[[#This Row],[Date of Call]])+1) -> 2023 | J25: =TEXT(calls[[#This Row],[Date of Call]],"DDDD") -> Saturday | K25: {=_xlfn.IFS(calls[[#This Row],[Duration]]<=10,"Under 10 mins", calls[[#This Row],[Duration]]<=30, "10 to 30 mins", calls[[#This Row],[Duration]]<=60, "30 to 60 mins", calls[[#This Row],[Duration]]<=120, "1 to 2 hours", TRUE, "More than 2 hours")} -> 30 to 60 mins | L25: =ROUND(calls[[#This Row],[Satisfaction Rating]],0) -> 5
B26: Call_7293 | C26: C0003 | D26: 67 | E26: R04 | F26: 44934 | G26: 165 | H26: 4.5 | I26: =IF(MONTH(calls[[#This Row],[Date of Call]])<=6, YEAR(calls[[#This Row],[Date of Call]]), YEAR(calls[[#This Row],[Date of Call]])+1) -> 2023 | J26: =TEXT(calls[[#This Row],[Date of Call]],"DDDD") -> Sunday | K26: {=_xlfn.IFS(calls[[#This Row],[Duration]]<=10,"Under 10 mins", calls[[#This Row],[Duration]]<=30, "10 to 30 mins", calls[[#This Row],[Duration]]<=60, "30 to 60 mins", calls[[#This Row],[Duration]]<=120, "1 to 2 hours", TRUE, "More than 2 hours")} -> 1 to 2 hours | L26: =ROUND(calls[[#This Row],[Satisfaction Rating]],0) -> 5
B27: Call_7294 | C27: C0015 | D27: 58 | E27: R02 | F27: 44934 | G27: 140 | H27: 2.1 | I27: =IF(MONTH(calls[[#This Row],[Date of Call]])<=6, YEAR(calls[[#This Row],[Date of Call]]), YEAR(calls[[#This Row],[Date of Call]])+1) -> 2023 | J27: =TEXT(calls[[#This Row],[Date of Call]],"DDDD") -> Sunday | K27: {=_xlfn.IFS(calls[[#This Row],[Duration]]<=10,"Under 10 mins", calls[[#This Row],[Duration]]<=30, "10 to 30 mins", calls[[#This Row],[Duration]]<=60, "30 to 60 mins", calls[[#This Row],[Duration]]<=120, "1 to 2 hours", TRUE, "More than 2 hours")} -> 30 to 60 mins | L27: =ROUND(calls[[#This Row],[Satisfaction Rating]],0) -> 2
B28: Call_7295 | C28: C0010 | D28: 54 | E28: R01 | F28: 44934 | G28: 111 | H28: 3.3 | I28: =IF(MONTH(calls[[#This Row],[Date of Call]])<=6, YEAR(calls[[#This Row],[Date of Call]]), YEAR(calls[[#This Row],[Date of Call]])+1) -> 2023 | J28: =TEXT(calls[[#This Row],[Date of Call]],"DDDD") -> Sunday | K28: {=_xlfn.IFS(calls[[#This Row],[Duration]]<=10,"Under 10 mins", calls[[#This Row],[Duration]]<=30, "10 to 30 mins", calls[[#This Row],[Duration]]<=60, "30 to 60 mins", calls[[#This Row],[Duration]]<=120, "1 to 2 hours", TRUE, "More than 2 hours")} -> 30 to 60 mins | L28: =ROUND(calls[[#This Row],[Satisfaction Rating]],0) -> 3
B29: Call_7296 | C29: C0012 | D29: 28 | E29: R05 | F29: 44935 | G29: 63 | H29: 4.1 | I29: =IF(MONTH(calls[[#This Row],[Date of Call]])<=6, YEAR(calls[[#This Row],[Date of Call]]), YEAR(calls[[#This Row],[Date of Call]])+1) -> 2023 | J29: =TEXT(calls[[#This Row],[Date of Call]],"DDDD") -> Monday | K29: {=_xlfn.IFS(calls[[#This Row],[Duration]]<=10,"Under 10 mins", calls[[#This Row],[Duration]]<=30, "10 to 30 mins", calls[[#This Row],[Duration]]<=60, "30 to 60 mins", calls[[#This Row],[Duration]]<=120, "1 to 2 hours", TRUE, "More than 2 hours")} -> 10 to 30 mins | L29: =ROUND(calls[[#This Row],[Satisfaction Rating]],0) -> 4
B30: Call_7297 | C30: C0002 | D30: 73 | E30: R05 | F30: 44935 | G30: 80 | H30: 4.2 | I30: =IF(MONTH(calls[[#This Row],[Date of Call]])<=6, YEAR(calls[[#This Row],[Date of Call]]), YEAR(calls[[#This Row],[Date of Call]])+1) -> 2023 | J30: =TEXT(calls[[#This Row],[Date of Call]],"DDDD") -> Monday | K30: {=_xlfn.IFS(calls[[#This Row],[Duration]]<=10,"Under 10 mins", calls[[#This Row],[Duration]]<=30, "10 to 30 mins", calls[[#This Row],[Duration]]<=60, "30 to 60 mins", calls[[#This Row],[Duration]]<=120, "1 to 2 hours", TRUE, "More than 2 hours")} -> 1 to 2 hours | L30: =ROUND(calls[[#This Row],[Satisfaction Rating]],0) -> 4
... B1003: Call_8270 | C1003: C0009 | D1003: 114 | E1003: R01 | F1003: 45291 | G1003: 40 | H1003: 3.9 | I1003: =IF(MONTH(calls[[#This Row],[Date of Call]])<=6, YEAR(calls[[#This Row],[Date of Call]]), YEAR(calls[[#This Row],[Date of Call]])+1) -> 2024 | J1003: =TEXT(calls[[#This Row],[Date of Call]],"DDDD") -> Sunday | K1003: {=_xlfn.IFS(calls[[#This Row],[Duration]]<=10,"Under 10 mins", calls[[#This Row],[Duration]]<=30, "10 to 30 mins", calls[[#This Row],[Duration]]<=60, "30 to 60 mins", calls[[#This Row],[Duration]]<=120, "1 to 2 hours", TRUE, "More than 2 hours")} -> 1 to 2 hours | L1003: =ROUND(calls[[#This Row],[Satisfaction Rating]],0) -> 4

Sheet Assets
E2: Rep ID | F2: Rep Image
E3: R01 | F3: #VALUE!
E4: R02 | F4: #VALUE!
E5: R03 | F5: #VALUE!
E6: R04 | F6: #VALUE!
E7: R05

Sheet customer center report
D1: CALL CENTER REPORT - 2025
H6: `
F12: `
O13: =pivot!F51 -> R01 | P13: =pivot!G51 -> R02 | Q13: =pivot!H51 -> R03 | R13: =pivot!I51 -> R04 | S13: =pivot!J51 -> R05 | T13: TOTAL
N14: =IF(pivot!E52="", "",pivot!E52) -> Cincinnati | O14: =IF(pivot!F52="", "",pivot!F52) | P14: =IF(pivot!G52="", "",pivot!G52) | Q14: =IF(pivot!H52="", "",pivot!H52) | R14: =IF(pivot!I52="", "",pivot!I52) | S14: =IF(pivot!J52="", "",pivot!J52) | T14: =IF(pivot!K52="", "",pivot!K52)
N15: =IF(pivot!E53="", "",pivot!E53) -> C0003 | O15: =IF(pivot!F53="", "",pivot!F53) -> 891 | P15: =IF(pivot!G53="", "",pivot!G53) -> 1332 | Q15: =IF(pivot!H53="", "",pivot!H53) -> 1282 | R15: =IF(pivot!I53="", "",pivot!I53) -> 739 | S15: =IF(pivot!J53="", "",pivot!J53) -> 560 | T15: =IF(pivot!K53="", "",pivot!K53) -> 4804
N16: =IF(pivot!E54="", "",pivot!E54) -> C0004 | O16: =IF(pivot!F54="", "",pivot!F54) -> 1991 | P16: =IF(pivot!G54="", "",pivot!G54) -> 1982 | Q16: =IF(pivot!H54="", "",pivot!H54) -> 1206 | R16: =IF(pivot!I54="", "",pivot!I54) -> 884 | S16: =IF(pivot!J54="", "",pivot!J54) -> 1722 | T16: =IF(pivot!K54="", "",pivot!K54) -> 7785
N17: =IF(pivot!E55="", "",pivot!E55) -> C0011 | O17: =IF(pivot!F55="", "",pivot!F55) -> 1163 | P17: =IF(pivot!G55="", "",pivot!G55) -> 1180 | Q17: =IF(pivot!H55="", "",pivot!H55) -> 1616 | R17: =IF(pivot!I55="", "",pivot!I55) -> 1043 | S17: =IF(pivot!J55="", "",pivot!J55) -> 1747 | T17: =IF(pivot!K55="", "",pivot!K55) -> 6749
N18: =IF(pivot!E56="", "",pivot!E56) -> C0012 | O18: =IF(pivot!F56="", "",pivot!F56) -> 1438 | P18: =IF(pivot!G56="", "",pivot!G56) -> 1616 | Q18: =IF(pivot!H56="", "",pivot!H56) -> 866 | R18: =IF(pivot!I56="", "",pivot!I56) -> 829 | S18: =IF(pivot!J56="", "",pivot!J56) -> 2070 | T18: =IF(pivot!K56="", "",pivot!K56) -> 6819
N19: =IF(pivot!E57="", "",pivot!E57) -> Cleveland | O19: =IF(pivot!F57="", "",pivot!F57) | P19: =IF(pivot!G57="", "",pivot!G57) | Q19: =IF(pivot!H57="", "",pivot!H57) | R19: =IF(pivot!I57="", "",pivot!I57) | S19: =IF(pivot!J57="", "",pivot!J57) | T19: =IF(pivot!K57="", "",pivot!K57)
N20: =IF(pivot!E58="", "",pivot!E58) -> C0002 | O20: =IF(pivot!F58="", "",pivot!F58) -> 1233 | P20: =IF(pivot!G58="", "",pivot!G58) -> 223 | Q20: =IF(pivot!H58="", "",pivot!H58) -> 1680 | R20: =IF(pivot!I58="", "",pivot!I58) -> 990 | S20: =IF(pivot!J58="", "",pivot!J58) -> 1508 | T20: =IF(pivot!K58="", "",pivot!K58) -> 5634
N21: =IF(pivot!E59="", "",pivot!E59) -> C0007 | O21: =IF(pivot!F59="", "",pivot!F59) -> 1598 | P21: =IF(pivot!G59="", "",pivot!G59) -> 1907 | Q21: =IF(pivot!H59="", "",pivot!H59) -> 869 | R21: =IF(pivot!I59="", "",pivot!I59) -> 1426 | S21: =IF(pivot!J59="", "",pivot!J59) -> 1416 | T21: =IF(pivot!K59="", "",pivot!K59) -> 7216
N22: =IF(pivot!E60="", "",pivot!E60) -> C0008 | O22: =IF(pivot!F60="", "",pivot!F60) -> 900 | P22: =IF(pivot!G60="", "",pivot!G60) -> 1016 | Q22: =IF(pivot!H60="", "",pivot!H60) -> 960 | R22: =IF(pivot!I60="", "",pivot!I60) -> 940 | S22: =IF(pivot!J60="", "",pivot!J60) -> 1193 | T22: =IF(pivot!K60="", "",pivot!K60) -> 5009
N23: =IF(pivot!E61="", "",pivot!E61) -> C0010 | O23: =IF(pivot!F61="", "",pivot!F61) -> 900 | P23: =IF(pivot!G61="", "",pivot!G61) -> 1374 | Q23: =IF(pivot!H61="", "",pivot!H61) -> 1617 | R23: =IF(pivot!I61="", "",pivot!I61) -> 1314 | S23: =IF(pivot!J61="", "",pivot!J61) -> 941 | T23: =IF(pivot!K61="", "",pivot!K61) -> 6146
N24: =IF(pivot!E62="", "",pivot!E62) -> C0013 | O24: =IF(pivot!F62="", "",pivot!F62) -> 1255 | P24: =IF(pivot!G62="", "",pivot!G62) -> 516 | Q24: =IF(pivot!H62="", "",pivot!H62) -> 1874 | R24: =IF(pivot!I62="", "",pivot!I62) -> 1863 | S24: =IF(pivot!J62="", "",pivot!J62) -> 1722 | T24: =IF(pivot!K62="", "",pivot!K62) -> 7230
N25: =IF(pivot!E63="", "",pivot!E63) -> C0015 | O25: =IF(pivot!F63="", "",pivot!F63) -> 1138 | P25: =IF(pivot!G63="", "",pivot!G63) -> 1898 | Q25: =IF(pivot!H63="", "",pivot!H63) -> 1482 | R25: =IF(pivot!I63="", "",pivot!I63) -> 846 | S25: =IF(pivot!J63="", "",pivot!J63) -> 1154 | T25: =IF(pivot!K63="", "",pivot!K63) -> 6518
N26: =IF(pivot!E64="", "",pivot!E64) -> Columbus | O26: =IF(pivot!F64="", "",pivot!F64) | P26: =IF(pivot!G64="", "",pivot!G64) | Q26: =IF(pivot!H64="", "",pivot!H64) | R26: =IF(pivot!I64="", "",pivot!I64) | S26: =IF(pivot!J64="", "",pivot!J64) | T26: =IF(pivot!K64="", "",pivot!K64)
L27: =pivot!C83 -> % of calls:22% | N27: =IF(pivot!E65="", "",pivot!E65) -> C0001 | O27: =IF(pivot!F65="", "",pivot!F65) -> 1655 | P27: =IF(pivot!G65="", "",pivot!G65) -> 805 | Q27: =IF(pivot!H65="", "",pivot!H65) -> 2263 | R27: =IF(pivot!I65="", "",pivot!I65) -> 987 | S27: =IF(pivot!J65="", "",pivot!J65) -> 1075 | T27: =IF(pivot!K65="", "",pivot!K65) -> 6785
L28: =pivot!C84 -> Call rank:1 | N28: =IF(pivot!E66="", "",pivot!E66) -> C0005 | O28: =IF(pivot!F66="", "",pivot!F66) -> 1104 | P28: =IF(pivot!G66="", "",pivot!G66) -> 2280 | Q28: =IF(pivot!H66="", "",pivot!H66) -> 1445 | R28: =IF(pivot!I66="", "",pivot!I66) -> 1722 | S28: =IF(pivot!J66="", "",pivot!J66) -> 1196 | T28: =IF(pivot!K66="", "",pivot!K66) -> 7747
L29: =pivot!C85 -> Amount rank:2 | N29: =IF(pivot!E67="", "",pivot!E67) -> C0006 | O29: =IF(pivot!F67="", "",pivot!F67) -> 372 | P29: =IF(pivot!G67="", "",pivot!G67) -> 1818 | Q29: =IF(pivot!H67="", "",pivot!H67) -> 1346 | R29: =IF(pivot!I67="", "",pivot!I67) -> 1156 | S29: =IF(pivot!J67="", "",pivot!J67) -> 1484 | T29: =IF(pivot!K67="", "",pivot!K67) -> 6176
N30: =IF(pivot!E68="", "",pivot!E68) -> C0009 | O30: =IF(pivot!F68="", "",pivot!F68) -> 1415 | P30: =IF(pivot!G68="", "",pivot!G68) -> 1271 | Q30: =IF(pivot!H68="", "",pivot!H68) -> 1214 | R30: =IF(pivot!I68="", "",pivot!I68) -> 1135 | S30: =IF(pivot!J68="", "",pivot!J68) -> 1566 | T30: =IF(pivot!K68="", "",pivot!K68) -> 6601
N31: =IF(pivot!E69=" ", " ",pivot!E69) -> C0014 | O31: =IF(pivot!F69=" ", " ",pivot!F69) -> 1362 | P31: =IF(pivot!G69=" ", " ",pivot!G69) -> 1363 | Q31: =IF(pivot!H69=" ", " ",pivot!H69) -> 1152 | R31: =IF(pivot!I69=" ", " ",pivot!I69) -> 777 | S31: =IF(pivot!J69=" ", " ",pivot!J69) -> 750 | T31: =IF(pivot!K69=" ", " ",pivot!K69) -> 5404
